Workbook

Sheet 📋 SYNC
B1: financas-2026 · Sync Sheet — REAL DATA LOADED
B2: BB Brasil CSV · MP Invoice JSON · BCB Câmbio PDF · Subscription xlsx · Loaded: 2026-07-02
B4: Last Updated | C4: 46205 | E4: Period | F4: Jan – Jun 2026
B6: DASHBOARD VARIABLE | C6: CURRENT VALUE | D6: PREV VALUE (manual) | E6: CHANGE | F6: STATUS | G6: SOURCE
B7: 🏦 BANKS
B8: BB Brasil (confirmed 30/06/2026) | C8: ='🏦 Banks'!C4 | D8: 0 | E8: =C8-D8 | F8: =IF(E8=0,"—",IF(E8>0,"▲ Up","▼ Down")) | G8: Extrato CSV ✅
B9: Mercado Pago | C9: ='🏦 Banks'!C5 | D9: 0 | E9: =C9-D9 | F9: =IF(E9=0,"—",IF(E9>0,"▲ Up","▼ Down")) | G9: Manual ⚠
B10: Banco Inter | C10: ='🏦 Banks'!C6 | D10: 0 | E10: =C10-D10 | F10: =IF(E10=0,"—",IF(E10>0,"▲ Up","▼ Down")) | G10: Manual ⚠
B11: TOTAL Liquidity | C11: ='🏦 Banks'!C9 | D11: 0 | E11: =C11-D11 | F11: =IF(E11=0,"—",IF(E11>0,"▲ Up","▼ Down")) | G11: Auto-sum
B12: 💳 CARD TRANSACTIONS
B13: AI/Assinaturas no cartão — 72 tx (subconjunto) | C13: =SUM('💳 Transactions'!G4:G200) | D13: 0 | E13: =C13-D13 | F13: =IF(E13=0,"—",IF(E13>0,"▲ Up","▼ Down")) | G13: Subset curado ⚠ (ver total real abaixo)
B14: CANCEL total (savings opportunity) | C14: =SUM('💳 Transactions'!H4:H200) | D14: 0 | E14: =C14-D14 | F14: =IF(E14=0,"—",IF(E14>0,"▲ Up","▼ Down")) | G14: Subscription xlsx ✅
B15: 🔄 SUBSCRIPTIONS
B16: Active monthly total — 15 services tracked | C16: =SUMIF('🔄 Subscriptions'!L4:L50,"KEEP",'🔄 Subscriptions'!I4:I50) | D16: 0 | E16: =C16-D16 | F16: =IF(E16=0,"—",IF(E16>0,"▲ Up","▼ Down")) | G16: Subscription xlsx ✅
B17: CANCEL savings/month | C17: =SUMIF('🔄 Subscriptions'!L4:L50,"CANCEL",'🔄 Subscriptions'!I4:I50) | D17: 0 | E17: =C17-D17 | F17: =IF(E17=0,"—",IF(E17>0,"▲ Up","▼ Down")) | G17: Subscription xlsx ✅
B18: ❌ CANCEL TRACKER
B19: # Cancel items (4 pre-loaded) | C19: =COUNTA('❌ Cancel Tracker'!B4:B50) | D19: 0 | E19: =C19-D19 | F19: =IF(E19=0,"—",IF(E19>0,"▲ Up","▼ Down")) | G19: Sub xlsx decisions ✅
B20: Monthly cost at stake | C20: =SUM('❌ Cancel Tracker'!D4:D50) | D20: 0 | E20: =C20-D20 | F20: =IF(E20=0,"—",IF(E20>0,"▲ Up","▼ Down")) | G20: Sub xlsx ✅
B21: 🌉 CASH BRIDGE — BB Brasil PIX
B22: PIX In (self-transfers received) | C22: =SUMIF('🌉 Cash Bridge'!C4:C100,"PIX In",'🌉 Cash Bridge'!E4:E100) | D22: 0 | E22: =C22-D22 | F22: =IF(E22=0,"—",IF(E22>0,"▲ Up","▼ Down")) | G22: Extrato CSV ✅
B23: PIX Out (sent) | C23: =SUMIF('🌉 Cash Bridge'!C4:C100,"PIX Out",'🌉 Cash Bridge'!E4:E100) | D23: 0 | E23: =C23-D23 | F23: =IF(E23=0,"—",IF(E23>0,"▲ Up","▼ Down")) | G23: Extrato CSV ✅
B24: FX / Câmbio outflows | C24: =SUM('🌉 Cash Bridge'!F4:F100) | D24: 0 | E24: =C24-D24 | F24: =IF(E24=0,"—",IF(E24>0,"▲ Up","▼ Down")) | G24: Extrato CSV ✅
B25: 🌍 INTERNATIONAL — BCB Câmbio 2026
B26: Outbound remittances — 32 ops total | C26: =SUMIF('🌍 International'!H4:H100,"Outbound",'🌍 International'!F4:F100) | D26: 0 | E26: =C26-D26 | F26: =IF(E26=0,"—",IF(E26>0,"▲ Up","▼ Down")) | G26: BCB PDF ✅
B27: IB Deposits (BRL) | C27: =SUMIF('🌍 International'!H4:H100,"IB Deposit",'🌍 International'!F4:F100) | D27: 0 | E27: =C27-D27 | F27: =IF(E27=0,"—",IF(E27>0,"▲ Up","▼ Down")) | G27: BCB PDF ✅
B28: Fund Deposits (BRL) | C28: =SUMIF('🌍 International'!H4:H100,"Fund Deposit",'🌍 International'!F4:F100) | D28: 0 | E28: =C28-D28 | F28: =IF(E28=0,"—",IF(E28>0,"▲ Up","▼ Down")) | G28: BCB PDF ✅
B29: Inbound (BRL) | C29: =SUMIF('🌍 International'!H4:H100,"Inbound",'🌍 International'!F4:F100) | D29: 0 | E29: =C29-D29 | F29: =IF(E29=0,"—",IF(E29>0,"▲ Up","▼ Down")) | G29: BCB PDF ✅
B31: 🟡 Yellow = manual input 🟢 Green = cross-sheet auto ⚫ Black = formula
B32: SUNDAY: 1) Add transactions 2) Update bank balances 3) Check SYNC 4) Paste into HTML dashboard Done.
B34: 💳 FATURAS COMPLETAS & MARKETPLACE (estava órfão)
B35: Total Fatura MP — 146 tx (cartão completo) | C35: =SUM('💳 MP Faturas'!D4:D149) | G35: MP Faturas ✅
B36: Mercado Livre — entregues | C36: =SUMIFS('🛒 ML iFood'!D4:D72,'🛒 ML iFood'!B4:B72,"Mercado Livre",'🛒 ML iFood'!F4:F72,"delivered") | G36: ML iFood ✅
B37: iFood — pedidos | C37: =SUMIFS('🛒 ML iFood'!D4:D72,'🛒 ML iFood'!B4:B72,"iFood") | G37: ML iFood ✅

Sheet 🏦 Banks
B1: 🏦 Banks & Account Balances — Jan–Jun 2026
B2: BB Brasil confirmed R$42,112.59 from extrato CSV 30/06/2026 · Other accounts require manual input
B3: Institution | C3: Balance (BRL) | D3: Prev Balance | E3: Change | F3: Last Updated | G3: Notes / Source
B4: BB Brasil | C4: 42112.59 | D4: 0 | E4: =C4-D4 | F4: 46203 | G4: ✅ Confirmed · Extrato CSV · Account 6627102
B5: Mercado Pago | C5: 10102.81 | D5: 0 | E5: =C5-D5 | F5: 46208 | G5: ✅ Confirmed · Extrato MP 29/06–05/07/2026 · Fatura jun R$6.813,48 paga (venc. 10/06)
B6: Banco Inter | C6: 0 | D6: 0 | E6: =C6-D6 | F6: 46205 | G6: ⚠ Manual input required · Account 000662710-2 (PIX active)
B7: BCB Registrato | C7: 0 | D7: 0 | E7: =C7-D7 | F7: 46205 | G7: ⚠ Registry only — no balance in CCS report
B9: TOTAL LIQUIDITY | C9: =SUM(C4:C8)
B11: BCB CCS ACTIVE: BB Brasil (2002) · Ágora CTVM · Bradrado · XP · CEF · Banco Inter (2016) · Mercado Pago (2020) · BIPA · Celcoin · Wise Brasil (all active 29/06/2026)

Sheet 💳 Transactions
B1: 💳 Card Transactions — Jan–Jun 2026 (72 entries) | L1: 📊 Spend by Decision
B2: Source: subscription_budget_dashboard_v3_deduped.xlsx · SUBCONJUNTO de 💳 MP Faturas (só cobranças AI/assinatura) — NÃO somar junto com MP Faturas | L2: Decision | M2: Total BRL | N2: Count
B3: # | C3: Invoice | D3: Tx Date | E3: Merchant | F3: Category | G3: Amount BRL | H3: USD | I3: Decision | J3: Operator Note | L3: KEEP | M3: =SUMIF($I$4:$I$75,L3,$G$4:$G$75) | N3: =COUNTIF($I$4:$I$75,L3)
B4: 1 | C4: 2026-01 | D4: 45996 | E4: OpenAI ChatGPT Subscription | F4: AI - General | G4: -110.54 | H4: 20 | I4: REVIEW | J4: Second ChatGPT monthly charge on prior card; duplicate with 20/12 | L4: CANCEL | M4: =SUMIF($I$4:$I$75,L4,$G$4:$G$75) | N4: =COUNTIF($I$4:$I$75,L4)
B5: 2 | C5: 2026-01 | D5: 45997 | E5: Paddle.net OnlineTLS | F5: Developer/Unknown | G5: -10.25 | I5: REVIEW | J5: Small developer subscription; verify need | L5: REVIEW | M5: =SUMIF($I$4:$I$75,L5,$G$4:$G$75) | N5: =COUNTIF($I$4:$I$75,L5)
B6: 3 | C6: 2026-01 | D6: 45999 | E6: Apple.com/Bill | F6: Apple/Cloud | G6: -21.9 | I6: KEEP | J6: Likely iCloud+ | L6: PAUSE | M6: =SUMIF($I$4:$I$75,L6,$G$4:$G$75) | N6: =COUNTIF($I$4:$I$75,L6)
B7: 4 | C7: 2026-01 | D7: 46000 | E7: GitHub, Inc. | F7: Developer | G7: -56.1 | H7: 10 | I7: REVIEW | J7: Recurring GitHub charge
B8: 5 | C8: 2026-01 | D8: 46001 | E8: Apple.com/Bill | F8: Apple/Cloud | G8: -19.9 | I8: KEEP | J8: Likely iCloud+
B9: 6 | C9: 2026-01 | D9: 46005 | E9: AI-PRO.ORG | F9: AI - Unknown | G9: -117.99 | I9: CANCEL | J9: Unclear AI subscription; high overlap risk
B10: 7 | C10: 2026-01 | D10: 46011 | E10: OpenAI ChatGPT Subscription | F10: AI - General | G10: -114.27 | H10: 20 | I10: KEEP | J10: Main assistant, but duplicate if multiple monthly charges
B11: 8 | C11: 2026-01 | D11: 46015 | E11: Manus AI | F11: AI - Agent/Credits | G11: -224.43 | H11: 39 | I11: CANCEL | J11: Usage/credits; high overlap
B12: 9 | C12: 2026-01 | D12: 46024 | E12: Apple.com/Bill | F12: AI - Research/Apple-billed | G12: -99.9 | I12: KEEP | J12: Perplexity/Grok Apple billing candidate; verify receipt
B13: 10 | C13: 2026-01 | D13: 46024 | E13: Manus AI | F13: AI - Agent/Credits | G13: -41.51 | I13: CANCEL | J13: Extra Manus charge
B14: 11 | C14: 2026-01 | D14: 46026 | E14: Manus AI | F14: AI - Agent/Credits | G14: -61.89 | H14: 10.99 | I14: CANCEL | J14: Extra Manus charge
B15: 12 | C15: 2026-02 | D15: 46030 | E15: OpenAI ChatGPT Subscription | F15: AI - General | G15: -111.58 | H15: 20 | I15: KEEP | J15: Monthly ChatGPT charge
B16: 13 | C16: 2026-02 | D16: 46030 | E16: Apple.com/Bill | F16: Apple/Cloud | G16: -21.9 | I16: KEEP | J16: Apple recurring charge
B17: 14 | C17: 2026-02 | D17: 46032 | E17: Apple.com/Bill | F17: Apple/Cloud | G17: -19.9 | I17: KEEP | J17: iCloud+
B18: 15 | C18: 2026-02 | D18: 46036 | E18: Manus AI | F18: AI - Agent/Credits | G18: -25.79 | H18: 4.63 | I18: CANCEL | J18: Small extra Manus charge
B19: 16 | C19: 2026-02 | D19: 46039 | E19: OpenAI ChatGPT Subscription | F19: AI - General | G19: -111.37 | H19: 20 | I19: REVIEW | J19: Second OpenAI subscription same cycle
B20: 17 | C20: 2026-02 | D20: 46041 | E20: LEMSQZY Pineapple App | F20: AI/App Unknown | G20: -111.11 | H20: 19.99 | I20: CANCEL | J20: Unclear app; likely duplicate subscription
B21: 18 | C21: 2026-02 | D21: 46043 | E21: Claude.ai Subscription | F21: AI - General/Coding | G21: -1138.5 | I21: CANCEL | J21: Extreme anomaly vs expected Claude Pro; investigate refund/cancellation
B22: 19 | C22: 2026-02 | D22: 46043 | E22: Manus AI | F22: AI - Agent/Credits | G22: -556.83 | H22: 100 | I22: CANCEL | J22: Large Manus credit purchase
B23: 20 | C23: 2026-02 | D23: 46049 | E23: Raycast.com | F23: Productivity/Automation | G23: -524.63 | H23: 96 | I23: REVIEW | J23: Annual/pro charge; only keep if central launcher
B24: 21 | C24: 2026-02 | D24: 46052 | E24: Apple.com/Bill | F24: AI - Research/Apple-billed | G24: -99.9 | I24: KEEP | J24: Likely Perplexity Pro Apple billing | L24: 📈 Spend by Category
B25: 22 | C25: 2026-02 | D25: 46056 | E25: Desktop Commander | F25: AI - Desktop Automation | G25: -272.21 | H25: 50 | I25: CANCEL | J25: Overlap with native scripts/ChatGPT/Cursor; verify if still billing | L25: Category | M25: Total BRL | N25: Count
B26: 23 | C26: 2026-03 | D26: 46058 | E26: OpenAI ChatGPT Subscription | F26: AI - General | G26: -108.89 | H26: 20 | I26: KEEP | J26: Monthly ChatGPT charge | L26: AI - General | M26: =SUMIF($F$4:$F$75,L26,$G$4:$G$75) | N26: =COUNTIF($F$4:$F$75,L26)
B27: 24 | C27: 2026-03 | D27: 46061 | E27: Apple.com/Bill | F27: Apple/Cloud | G27: -21.9 | I27: KEEP | J27: Apple recurring charge | L27: Developer/Unknown | M27: =SUMIF($F$4:$F$75,L27,$G$4:$G$75) | N27: =COUNTIF($F$4:$F$75,L27)
B28: 25 | C28: 2026-03 | D28: 46063 | E28: Apple.com/Bill | F28: Apple/Cloud | G28: -19.9 | I28: KEEP | J28: iCloud+ | L28: Apple/Cloud | M28: =SUMIF($F$4:$F$75,L28,$G$4:$G$75) | N28: =COUNTIF($F$4:$F$75,L28)
B29: 26 | C29: 2026-03 | D29: 46067 | E29: Anthropic | F29: AI - General/Coding | G29: -51.75 | I29: CANCEL | J29: Claude/Anthropic extra charge | L29: Developer | M29: =SUMIF($F$4:$F$75,L29,$G$4:$G$75) | N29: =COUNTIF($F$4:$F$75,L29)
B30: 27 | C30: 2026-03 | D30: 46070 | E30: OpenAI ChatGPT Subscription | F30: AI - General | G30: -108.27 | H30: 20 | I30: REVIEW | J30: Second OpenAI subscription same cycle | L30: AI - Unknown | M30: =SUMIF($F$4:$F$75,L30,$G$4:$G$75) | N30: =COUNTIF($F$4:$F$75,L30)
B31: 28 | C31: 2026-03 | D31: 46074 | E31: Manus AI | F31: AI - Agent/Credits | G31: -538.2 | H31: 100 | I31: CANCEL | J31: Large recurring credits | L31: AI - Agent/Credits | M31: =SUMIF($F$4:$F$75,L31,$G$4:$G$75) | N31: =COUNTIF($F$4:$F$75,L31)
B32: 29 | C32: 2026-03 | D32: 46081 | E32: Apple.com/Bill | F32: AI - Research/Apple-billed | G32: -99.9 | I32: KEEP | J32: Likely Perplexity/Grok Apple billing | L32: AI - Research/Apple-billed | M32: =SUMIF($F$4:$F$75,L32,$G$4:$G$75) | N32: =COUNTIF($F$4:$F$75,L32)
B33: 30 | C33: 2026-04 | D33: 46086 | E33: OpenAI ChatGPT Subscription | F33: AI - General | G33: -108.47 | H33: 20 | I33: KEEP | J33: Monthly ChatGPT charge | L33: AI/App Unknown | M33: =SUMIF($F$4:$F$75,L33,$G$4:$G$75) | N33: =COUNTIF($F$4:$F$75,L33)
B34: 31 | C34: 2026-04 | D34: 46089 | E34: Apple.com/Bill | F34: Apple/Cloud | G34: -21.9 | I34: KEEP | J34: Apple recurring charge | L34: AI - General/Coding | M34: =SUMIF($F$4:$F$75,L34,$G$4:$G$75) | N34: =COUNTIF($F$4:$F$75,L34)
B35: 32 | C35: 2026-04 | D35: 46089 | E35: GitHub, Inc. | F35: Developer | G35: -54.76 | H35: 10 | I35: REVIEW | J35: Recurring GitHub charge | L35: Productivity/Automation | M35: =SUMIF($F$4:$F$75,L35,$G$4:$G$75) | N35: =COUNTIF($F$4:$F$75,L35)
B36: 33 | C36: 2026-04 | D36: 46091 | E36: Apple.com/Bill | F36: Apple/Cloud | G36: -19.9 | I36: KEEP | J36: iCloud+ | L36: AI - Desktop Automation | M36: =SUMIF($F$4:$F$75,L36,$G$4:$G$75) | N36: =COUNTIF($F$4:$F$75,L36)
B37: 34 | C37: 2026-04 | D37: 46091 | E37: OpenRouter, Inc. | F37: AI API/Router | G37: -113.78 | H37: 21.1 | I37: PAUSE | J37: API usage; pause unless active project uses it | L37: AI API/Router | M37: =SUMIF($F$4:$F$75,L37,$G$4:$G$75) | N37: =COUNTIF($F$4:$F$75,L37)
B38: 35 | C38: 2026-04 | D38: 46098 | E38: OpenAI ChatGPT Subscription | F38: AI - General | G38: -108.89 | H38: 20 | I38: REVIEW | J38: Second OpenAI subscription same cycle | L38: AI/Productivity | M38: =SUMIF($F$4:$F$75,L38,$G$4:$G$75) | N38: =COUNTIF($F$4:$F$75,L38)
B39: 36 | C39: 2026-04 | D39: 46101 | E39: Google Brasil Pagamen | F39: AI/Productivity | G39: -96.99 | I39: REVIEW | J39: Google Pro subscription from original list | L39: AI - Coding | M39: =SUMIF($F$4:$F$75,L39,$G$4:$G$75) | N39: =COUNTIF($F$4:$F$75,L39)
B40: 37 | C40: 2026-04 | D40: 46102 | E40: Manus AI | F40: AI - Agent/Credits | G40: -546.48 | H40: 100 | I40: CANCEL | J40: Large recurring credits | L40: Productivity | M40: =SUMIF($F$4:$F$75,L40,$G$4:$G$75) | N40: =COUNTIF($F$4:$F$75,L40)
...

Sheet 🔄 Subscriptions
B1: 🔄 Subscriptions — 15 Services Tracked | N1: 📊 Monthly Cost by Decision
B2: Source: subscription_budget_dashboard_v3_deduped.xlsx · Decisions pre-assigned by operator | N2: Decision | O2: Monthly BRL | P2: Count
B3: Source | C3: Service | D3: Email | E3: Plan | F3: CCY | G3: Price | H3: Cycle | I3: Monthly BRL | J3: Category | K3: Dup Risk | L3: Decision | N3: KEEP | O3: =SUMIF($L$4:$L$18,N3,$I$4:$I$18) | P3: =COUNTIF($L$4:$L$18,N3)
B4: Direct AI | C4: Claude | D4: automacao.giovannini@gmail.com | E4: Pro | F4: BRL | G4: 92 | H4: monthly | I4: 92 | J4: AI - General/Coding | K4: HIGH | L4: CANCEL | N4: CANCEL | O4: =SUMIF($L$4:$L$18,N4,$I$4:$I$18) | P4: =COUNTIF($L$4:$L$18,N4)
B5: Direct AI | C5: Claude | D5: cadastros.online1979@gmail.com | E5: Pro | F5: BRL | G5: 92 | H5: monthly | I5: 92 | J5: AI - General/Coding | K5: HIGH | L5: CANCEL | N5: REVIEW | O5: =SUMIF($L$4:$L$18,N5,$I$4:$I$18) | P5: =COUNTIF($L$4:$L$18,N5)
B6: Direct AI | C6: ChatGPT | D6: giovannini.eduardo@gmail.com | E6: Plus | F6: USD | G6: 20 | H6: monthly | I6: 106 | J6: AI - General Assistant | K6: MEDIUM | L6: KEEP
B7: Direct AI | C7: Google | D7: cadastros.online1979@gmail.com | E7: Pro | F7: BRL | G7: 96.99 | H7: monthly | I7: 96.99 | J7: AI - General/Workspace | K7: HIGH | L7: REVIEW
B8: Direct AI | C8: Manus | D8: cadastro.giovannini@gmail.com | E8: Unknown / credits | F8: UNKNOWN | H8: UNKNOWN | I8: 0 | J8: AI - Agent/Credits | K8: UNKNOWN | L8: REVIEW
B9: Direct AI | C9: Manus | D9: automacao.giovannini@gmail.com | E9: Unknown / credits | F9: UNKNOWN | H9: UNKNOWN | I9: 418.43 | J9: AI - Agent/Credits | K9: UNKNOWN | L9: REVIEW
B10: Direct AI | C10: Cursor | D10: giovannini.eduardo@gmail.com | E10: Pro | F10: USD | G10: 20 | H10: monthly | I10: 106 | J10: AI - Coding Assistant | K10: MEDIUM | L10: KEEP
B11: Direct AI | C11: Desktop Commander | D11: automacao.giovannini@gmail.com | E11: Unlimited | F11: UNKNOWN | H11: UNKNOWN | I11: 45.37 | J11: AI - Desktop Automation | K11: UNKNOWN | L11: REVIEW
B12: Apple | C12: Filmora9 | D12: Unknown | E12: Annual Subscription | F12: BRL | G12: 184.9 | H12: annual | I12: 15.408333 | J12: Creative/Productivity | K12: LOW | L12: REVIEW
B13: Apple | C13: Grok | D13: Unknown | E13: SuperGrok | F13: BRL | G13: 149.9 | H13: monthly | I13: 149.9 | J13: AI - General/Media | K13: HIGH | L13: CANCEL
B14: Apple | C14: iCloud+ | D14: Unknown | E14: 200 GB storage | F14: BRL | G14: 19.9 | H14: monthly | I14: 19.9 | J14: Cloud/Storage | K14: LOW | L14: KEEP
B15: Apple | C15: Microsoft 365 Personal | D15: Unknown | E15: Personal | F15: BRL | G15: 509 | H15: annual | I15: 42.416667 | J15: Productivity/Cloud | K15: MEDIUM | L15: REVIEW
B16: Apple | C16: NordVPN | D16: Unknown | E16: Auto-renewable Subscription | F16: BRL | G16: 339.9 | H16: annual | I16: 28.325 | J16: Security/VPN | K16: LOW | L16: REVIEW
B17: Apple | C17: Perplexity | D17: Unknown | E17: Perplexity Pro for Mac | F17: BRL | G17: 99.9 | H17: monthly | I17: 99.9 | J17: AI - Research Assistant | K17: HIGH | L17: KEEP
B18: Apple | C18: TuneIn Radio | D18: Unknown | E18: TuneIn Premium | F18: BRL | G18: 31.9 | H18: monthly | I18: 31.9 | J18: Entertainment | K18: LOW | L18: CANCEL
B20: KEEP TOTAL/MONTH | I20: =SUMIF(L4:L19,"KEEP",I4:I19) | N20: ⚠️ Duplicate Risk Exposure
B21: CANCEL SAVINGS/MONTH | I21: =SUMIF(L4:L19,"CANCEL",I4:I19) | N21: Dup Risk | O21: Monthly BRL | P21: Count
B22: REVIEW TOTAL/MONTH | I22: =SUMIF(L4:L18,"REVIEW",I4:I18) | N22: HIGH | O22: =SUMIF($K$4:$K$18,N22,$I$4:$I$18) | P22: =COUNTIF($K$4:$K$18,N22)
N23: MEDIUM | O23: =SUMIF($K$4:$K$18,N23,$I$4:$I$18) | P23: =COUNTIF($K$4:$K$18,N23)
N24: LOW | O24: =SUMIF($K$4:$K$18,N24,$I$4:$I$18) | P24: =COUNTIF($K$4:$K$18,N24)
N25: UNKNOWN | O25: =SUMIF($K$4:$K$18,N25,$I$4:$I$18) | P25: =COUNTIF($K$4:$K$18,N25)

Sheet ❌ Cancel Tracker
B1: ❌ Cancel Tracker — 4 Services Flagged for Cancellation
B2: Pre-populated from CANCEL decisions in Subscription Dashboard. Update Status each Sunday.
B3: Service | C3: Account Email | D3: Monthly BRL | E3: Status | F3: Priority | G3: Target Date | H3: Notes
B4: Claude | C4: automacao.giovannini@gmail.com | D4: 92 | E4: Pending | F4: High | G4: Jul 2026 | H4: Duplicate Claude account; overlaps ChatGPT/Cursor/other Claude
B5: Claude | C5: cadastros.online1979@gmail.com | D5: 92 | E5: Pending | F5: High | G5: Jul 2026 | H5: Second Claude Pro account; pure duplicate
B6: Grok | C6: Unknown | D6: 149.9 | E6: Pending | F6: High | G6: Jul 2026 | H6: High overlap with ChatGPT/Claude/Google
B7: TuneIn Radio | C7: Unknown | D7: 31.9 | E7: Pending | F7: Low | G7: Jul 2026 | H7: Non-essential recurring subscription
B9: TOTAL MONTHLY SAVINGS IF ALL CANCELLED | D9: =SUM(D4:D8)

Sheet 🌉 Cash Bridge
B1: 🌉 Cash Bridge — BB Brasil Extrato (Jan–Jun 2026 · Account 6627102)
B2: Final balance R$42,112.59 confirmed · 30 movements parsed from extrato CSV
B3: Documented Gap (README) | C3: 122000 | E3: Final Balance (confirmed) | F3: 42112.59
B4: Date | C4: Type | D4: Description | E4: PIX Amount | F4: FX / Câmbio | G4: IOF Paid
B5: 46201 | C5: PIX In | D5: Eduardo Forster Giovannini | E5: 2000
B6: 46201 | C6: PIX In | D6: Eduardo F Giovannini | E6: 40000
B7: 46198 | C7: PIX In | D7: Eduardo F Giovannini | E7: 10
B8: 46178 | C8: PIX Out | D8: Eduardo Silva Dos Santos | E8: -480
B9: 46170 | C9: PIX Out | D9: Eduardo Silva Dos Santos | E9: -450
B10: 46167 | C10: PIX Out | D10: Eduardo Silva Dos Santos | E10: -470
B11: 46166 | C11: PIX Out | D11: Moacir Jose De Morais Filho | E11: -700
B12: 46164 | C12: PIX Out | D12: Lucas Rique Chaves Bezerra | E12: -1500
B13: 46164 | C13: PIX Out | D13: Lucas Rique Chaves Bezerra | E13: -500
B14: 46164 | C14: PIX Out | D14: Sbct Tech Solutions Llc | E14: -45000
B15: 46160 | C15: PIX In | D15: Eduardo F Giovannini | E15: 35000
B16: 46160 | C16: PIX Out | D16: Eduardo Giovannini | E16: -20000
... B18: 46153 | C18: PIX In | D18: Eduardo F Giovannini | E18: 40000
B19: 46153 | C19: Câmbio | D19: Envio - remessa internacional | F19: -74340.4
B20: 46153 | C20: IOF | D20: IOF - Operação de câmbio | G20: -2601.91
B21: 46150 | C21: PIX In | D21: Eduardo F Giovannini | E21: 40000
B22: 46149 | C22: Câmbio | D22: Envio - remessa internacional | F22: -24939.84
B23: 46149 | C23: IOF | D23: IOF - Operação de câmbio | G23: -872.89
B24: 46140 | C24: PIX In | D24: Eduardo F Giovannini | E24: 40000
B25: 46140 | C25: PIX Out | D25: Gloria Raquel M C Nobrega | E25: -50
B26: 46140 | C26: PIX Out | D26: Mag Administracao De Negocios Ltda | E26: -10
B27: 46140 | C27: PIX Out | D27: Eduardo Silva Dos Santos | E27: -470
B28: 46136 | C28: PIX Out | D28: 37202818 Jose Periclis De Sousa Da Costa | E28: -6800
B29: 46133 | C29: PIX Out | D29: Eduardo Forster Giovannini | E29: -3000
B30: 46101 | C30: PIX Out | D30: Eduardo Silva Dos Santos | E30: -350
B31: 46098 | C31: PIX Out | D31: Iago Kevyn Santos Moura | E31: -500
B32: 46096 | C32: PIX Out | D32: Eduardo Forster Giovannini | E32: -6000
B33: 46096 | C33: PIX Out | D33: Mercado Pago Instituicao De Pagamento Ltda | E33: -4582.41
B34: 46064 | C34: PIX In | D34: Eduardo F Giovannini | E34: 40000
B36: NET PIX FLOW | E36: =SUM(E5:E35)
B37: TOTAL CÂMBIO OUT | F37: =SUM(F5:F35)
B38: TOTAL IOF PAID | G38: =SUM(G5:G35)
B40: SOMA MOVIMENTOS (PIX+Câmbio+IOF) | E40: =E36+F37+G38
B41: RESÍDUO vs Saldo Final (F3) — deve ~0 | E41: =E40-F3
B42: ⓘ Movimentos explicam o saldo até R$20,01. C3 (R$122K) é narrativa do README, não reconciliada aqui.

Sheet 🌍 International
B1: 🌍 International — BCB Câmbio 2026 (32 operations)
B2: Source: Cambio-21596563800-202606-29062026.pdf · Período 01/01/2026–28/06/2026 · Self-transfers + IB + Funds + Inbound
B3: Date | C3: Institution | D3: Destination / Counterpart | E3: FCY Amt | F3: BRL Amount | G3: CCY | H3: Direction | I3: FX Rate | J3: Nature
B4: 46048 | C4: Banco Topázio | D4: Interactive Brokers | E4: 200 | F4: 1071.22 | G4: USD | H4: IB Deposit | I4: 5.3561 | J4: 91992 IB deposit
B5: 46049 | C5: BB Brasil | D5: USA - Own Account | E5: 3000 | F5: 15886.01 | G5: USD | H5: Outbound | I5: 5.2953 | J5: 67995 Self-transfer
B6: 46052 | C6: BB Brasil | D6: USA - Own Account | E6: 3000 | F6: 16063.89 | G6: USD | H6: Outbound | I6: 5.3546 | J6: 67995 Self-transfer
B7: 46062 | C7: BB Brasil | D7: USA - Own Account | E7: 3000 | F7: 15868.79 | G7: USD | H7: Outbound | I7: 5.2896 | J7: 67995 Self-transfer
B8: 46064 | C8: BB Brasil | D8: USA - Own Account | E8: 3000 | F8: 15789.96 | G8: USD | H8: Outbound | I8: 5.2633 | J8: 67995 Self-transfer
B9: 46084 | C9: BB Brasil | D9: USA - Own Account | E9: 3000 | F9: 16024.35 | G9: USD | H9: Outbound | I9: 5.3414 | J9: 67995 Self-transfer
B10: 46094 | C10: BB Brasil | D10: USA - Own Account | E10: 3000 | F10: 15877.18 | G10: USD | H10: Outbound | I10: 5.2924 | J10: 67995 Self-transfer
B11: 46099 | C11: BB Brasil | D11: USA - Own Account | E11: 3000 | F11: 15963.15 | G11: USD | H11: Outbound | I11: 5.3211 | J11: 67995 Self-transfer
B12: 46134 | C12: BB Brasil | D12: USA - Own Account | E12: 3000 | F12: 15878.08 | G12: USD | H12: Outbound | I12: 5.2927 | J12: 67995 Self-transfer
B13: 46142 | C13: Banco Topázio | D13: Interactive Brokers | E13: 100 | F13: 503.62 | G13: USD | H13: IB Deposit | I13: 5.0362 | J13: 91992 IB deposit
B14: 46149 | C14: BB Brasil | D14: USA - Own Account | E14: 3000 | F14: 15132.89 | G14: USD | H14: Outbound | I14: 5.0443 | J14: 67995 Self-transfer
B15: 46149 | C15: Banco Inter | D15: USA - Own Account | E15: 5000 | F15: 24939.84 | G15: USD | H15: Outbound | I15: 4.988 | J15: 67995 Self-transfer via Inter
... B22: 46162 | C22: Banco Topázio | D22: Interactive Brokers | E22: 6212.32 | F22: 31651.83 | G22: USD | H22: IB Deposit | I22: 5.0949 | J22: 91992 IB deposit
B23: 46164 | C23: Banco Topázio | D23: Fundos investimento BRL | F23: 45000 | G23: BRL | H23: Fund Deposit | J23: 67043 Fund capital
B24: 46168 | C24: BB Brasil | D24: USA - Own Account | E24: 10000 | F24: 51027.68 | G24: USD | H24: Outbound | I24: 5.1028 | J24: 67995 Self-transfer
B25: 46170 | C25: BB Brasil | D25: USA - Own Account | E25: 5000 | F25: 25650.76 | G25: USD | H25: Outbound | I25: 5.1302 | J25: 67995 Self-transfer
B26: 46170 | C26: Banco Topázio | D26: Interactive Brokers | E26: 20000 | F26: 101772.38 | G26: USD | H26: IB Deposit | I26: 5.0886 | J26: 91992 IB deposit
B27: 46178 | C27: Wise Brasil | D27: UK - Eduardo Giovannini | E27: 100 | F27: 514.21 | G27: USD | H27: Outbound | I27: 5.1421 | J27: 67995 Wise UK
B28: 46178 | C28: Banco Topázio | D28: Fundos investimento BRL | F28: 78323.92 | G28: BRL | H28: Fund Deposit | J28: 67043 Fund capital
B29: 46178 | C29: BB Brasil | D29: USA → Eduardo Forster Giovannini | F29: 73857 | G29: BRL | H29: Inbound | J29: 72629 Inbound from USA
B30: 46189 | C30: Ouribank | D30: Inbound payment order | F30: 25000 | G30: BRL | H30: Inbound | J30: 72629 Inbound payment order
B31: 46192 | C31: Banco Topázio | D31: Fundos investimento BRL | F31: 52441.91 | G31: BRL | H31: Fund Deposit | J31: 67043 Fund capital
B32: 46195 | C32: BB Brasil | D32: USA - Own Account | E32: 46229.38 | F32: 241545.87 | G32: USD | H32: Outbound | I32: 5.2245 | J32: 67995 Self-transfer
B33: 46195 | C33: Wise Brasil | D33: UK - Eduardo Giovannini | E33: 17000 | F33: 87442.26 | G33: USD | H33: Outbound | I33: 5.1436 | J33: 67995 Wise UK
B34: 46195 | C34: Wise Brasil | D34: Interactive Brokers | E34: 7454.1 | F34: 38396.86 | G34: USD | H34: IB Deposit | I34: 5.151 | J34: 91992 IB via Wise
B35: 46199 | C35: Wise Brasil | D35: Interactive Brokers | E35: 3834.82 | F35: 19195.81 | G35: USD | H35: IB Withdraw | I35: 5.1783 | J35: 91992 IB withdrawal via Wise
B37: ──── 2024 Historical Travel FX (context only) ────
B38: 45531 | C38: Daycoval | D38: Switzerland Travel | E38: 800 | F38: 5618.2 | G38: CHF | H38: Travel FX | I38: 7.0228 | J38: 32999 Travel
B39: 45531 | C39: Daycoval | D39: USA Travel | E39: 2000 | F39: 11473.79 | G39: USD | H39: Travel FX | I39: 5.7369 | J39: 32999 Travel
B40: 45615 | C40: Daycoval | D40: Switzerland Travel | E40: 1500 | F40: 10534.12 | G40: CHF | H40: Travel FX | I40: 7.0228 | J40: 32999 Travel
B43: OUTBOUND 2026 | F43: =SUMIF(H4:H35,"Outbound",F4:F35)
B44: INBOUND 2026 | F44: =SUMIF(H4:H35,"Inbound",F4:F35)

Sheet 📅 Weekly
B1: 📅 Weekly Tracker — Jan–Jun 2026 (derived from card transactions)
B2: Weekly card spend derived by matching transaction dates. Review and supplement with Uber/cash/PIX spend.
B3: Week # | C3: Week Start | D3: Week End | E3: Card Spend | F3: # Txs | G3: Notes
B4: 1 | C4: 46027 | D4: 46033 | E4: -1032.06 | F4: 14 | G4: Inclui 11 lançamentos pré-período (dez-2025 + início jan, R$878.68)
B5: 2 | C5: 46034 | D5: 46040 | E5: -137.16 | F5: 2
B6: 3 | C6: 46041 | D6: 46047 | E6: -1806.44 | F6: 3
B7: 4 | C7: 46048 | D7: 46054 | E7: -624.53 | F7: 2
B8: 5 | C8: 46055 | D8: 46061 | E8: -403 | F8: 3
B9: 6 | C9: 46062 | D9: 46068 | E9: -71.65 | F9: 2
B10: 7 | C10: 46069 | D10: 46075 | E10: -646.47 | F10: 2
B11: 8 | C11: 46076 | D11: 46082 | E11: -99.9 | F11: 1
B12: 9 | C12: 46083 | D12: 46089 | E12: -185.13 | F12: 3
B13: 10 | C13: 46090 | D13: 46096 | E13: -133.68 | F13: 2
B14: 11 | C14: 46097 | D14: 46103 | E14: -752.36 | F14: 3
B15: 12 | C15: 46104 | D15: 46110
B16: 13 | C16: 46111 | D16: 46117 | E16: -400.09 | F16: 4
B17: 14 | C17: 46118 | D17: 46124 | E17: -95.21 | F17: 3
B18: 15 | C18: 46125 | D18: 46131 | E18: -103.5 | F18: 1
B19: 16 | C19: 46132 | D19: 46138 | E19: -1163.94 | F19: 4
B20: 17 | C20: 46139 | D20: 46145 | E20: -677.26 | F20: 5
B21: 18 | C21: 46146 | D21: 46152 | E21: -172.68 | F21: 3
B22: 19 | C22: 46153 | D22: 46159 | E22: -183.67 | F22: 2
B23: 20 | C23: 46160 | D23: 46166 | E23: -800.42 | F23: 5
B24: 21 | C24: 46167 | D24: 46173 | E24: -317.25 | F24: 3
B25: 22 | C25: 46174 | D25: 46180 | E25: -425.12 | F25: 5
B26: 23 | C26: 46181 | D26: 46187
B27: 24 | C27: 46188 | D27: 46194
B28: 25 | C28: 46195 | D28: 46201
B29: 26 | C29: 46202 | D29: 46208
B30: TOTAL | E30: =SUM(E4:E29) | F30: =SUM(F4:F29)
B31: ✓ RECONCILE vs Transactions (deve ser 0) | E31: =E30-'💳 Transactions'!G76

Sheet 📖 Instructions
B1: 📖 financas-2026 · Solution C · Real Data Operating Guide
B3: DATA LOADED — STATUS
B4: ✅ 💳 Transactions: 72 card entries Jan–Jun 2026 (subscription_budget_dashboard_v3_deduped.xlsx) ✅ 🔄 Subscriptions: 15 services with KEEP/CANCEL/REVIEW decisions already assigned ✅ ❌ Cancel Tracker: All CANCEL items pre-loaded (status = Pending, update each Sunday) ✅ 🏦 Banks: BB Brasil R$42,112.59 confirmed · MP / Inter / BCB need manual balance input ✅ 🌉 Cash Bridge: All BB Brasil extrato movements Jan–Jun 2026 fully parsed ✅ 🌍 International: 32 BCB Câmbio 2026 operations (self-transfers + IB + funds + inbound) ✅ 📅 Weekly: Derived from card transaction dates — review for completeness ⚠ MP JSON (fatura Jun 2026) not merged to avoid duplicates — check transactions for coverage
B6: SUNDAY RITUAL (30–45 min)
B7: 1. 💳 Transactions — add any charges not yet captured (check MP app / bank statement) 2. 🏦 Banks — update Mercado Pago, Banco Inter, BCB balances manually (3 cells) 3. 🔄 Subscriptions — review status; advance any REVIEW decisions 4. ❌ Cancel Tracker — update Status per service (Pending → In Progress → Cancelled) 5. 📋 SYNC — all totals auto-calculate. Review the 12 key metrics. 6. Open HTML dashboard in BBEdit / TextEdit → update JS data variables from SYNC 7. Save HTML → open in Safari → verify charts updated → done.
B9: PHASE 2 GATE
B10: Do NOT begin SwiftUI / Vision / Foundation Models until ALL are true: ✓ 3 complete Sunday cycles documented ✓ PDF ingestion confirmed as the real operational bottleneck ✓ Time is available for a native build ✓ HTML no longer solves the need This file is designed to run for months without modification.

Sheet 💳 MP Faturas
A1: 💳 Mercado Pago — Faturas Cartão de Crédito 2026
A2: ="Total: R$"&TEXT(SUM(D4:D149),"#,##0.00") | C2: =COUNT(D4:D149)&" transações" | E2: Limite: R$35.000,00 | G2: Cartão Visa ****9433
A3: Data | B3: Fatura | C3: Merchant / Estabelecimento | D3: Valor (R$) | E3: Categoria | F3: Internacional | G3: Fonte | H3: #
A4: 2026-01-06 | B4: 2026-02 | C4: IFD*PIZZA NOW INTERMARES | D4: 173.79 | E4: Delivery/iFood | F4: Não | G4: MP Cartão | H4: 1
A5: 2026-01-08 | B5: 2026-02 | C5: Compra internacional em OPENAI *CHATGPT SUBSCR | D5: 111.58 | E5: IA/Tecnologia | F5: Sim | G5: MP Cartão | H5: 2
A6: 2026-01-08 | B6: 2026-02 | C6: APPLE.COM/BILL | D6: 21.9 | E6: Assinatura | F6: Não | G6: MP Cartão | H6: 3
A7: 2026-01-10 | B7: 2026-02 | C7: IFD*34531468 EDWIN LEI | D7: 111.6 | E7: Delivery/iFood | F7: Não | G7: MP Cartão | H7: 4
A8: 2026-01-10 | B8: 2026-02 | C8: APPLE.COM/BILL | D8: 19.9 | E8: Assinatura | F8: Não | G8: MP Cartão | H8: 5
A9: 2026-01-13 | B9: 2026-02 | C9: MP*EDUARDOGIOVAN | D9: 0.78 | E9: Outros | F9: Sim | G9: MP Cartão | H9: 6
A10: 2026-01-14 | B10: 2026-02 | C10: Compra internacional em MANUS AI | D10: 25.79 | E10: IA/Tecnologia | F10: Sim | G10: MP Cartão | H10: 7
A11: 2026-01-15 | B11: 2026-02 | C11: DL*Starlink Braz | D11: 235.52 | E11: Internet | F11: Não | G11: MP Cartão | H11: 8
A12: 2026-01-16 | B12: 2026-02 | C12: MP*LOTERIASONLINEU1AQ | D12: 143.6 | E12: Loteria | F12: Sim | G12: MP Cartão | H12: 9
A13: 2026-01-16 | B13: 2026-02 | C13: IFD*FORMAGGIO RESTAURANTE | D13: 191.8 | E13: Delivery/iFood | F13: Sim | G13: MP Cartão | H13: 10
A14: 2026-01-17 | B14: 2026-02 | C14: Compra internacional em OPENAI *CHATGPT SUBSCR | D14: 111.37 | E14: IA/Tecnologia | F14: Sim | G14: MP Cartão | H14: 11
A15: 2026-01-17 | B15: 2026-02 | C15: MP*LOTERIASONLINE542V | D15: 111 | E15: Loteria | F15: Sim | G15: MP Cartão | H15: 12
... A149: 2026-06-05 | B149: 2026-06 | C149: Compra internacional em WWW.PERPLEXITY.AI | D149: 78.25 | E149: IA/Tecnologia | F149: Sim | G149: MP Cartão | H149: 146
C151: TOTAL FATURA (live) | D151: =SUM(D4:D149)
C152: Nº transações | D152: =COUNT(D4:D149)

Sheet 🛒 ML iFood
A1: 🛒 Mercado Livre + iFood — Histórico de Compras & Pedidos 2026
A2: ="ML Entregues: R$"&TEXT(SUMIFS(D4:D72,B4:B72,"Mercado Livre",F4:F72,"delivered"),"#,##0.00") | C2: ="iFood: R$"&TEXT(SUMIFS(D4:D72,B4:B72,"iFood"),"#,##0.00")&" ("&COUNTIF(B4:B72,"iFood")&" pedidos, "&COUNTIFS(B4:B72,"iFood",D4:D72,">0")&" com valor)" | E2: ="Total Combinado: R$"&TEXT(SUMIFS(D4:D72,B4:B72,"Mercado Livre",F4:F72,"delivered")+SUMIFS(D4:D72,B4:B72,"iFood"),"#,##0.00")
A3: Data | B3: Plataforma | C3: Produto / Restaurante | D3: Valor (R$) | E3: Categoria | F3: Status | G3: #
A4: 2026-06-16 | B4: Mercado Livre | C4: Suporte Monitor Articulado Portátil Dobrável | D4: 144 | E4: Home Office | F4: delivered | G4: 1
A5: 2026-06-08 | B5: Mercado Livre | C5: Filtro De Ar Descartável Cpap Airmini Resmed | D5: 41.65 | E5: Saúde/CPAP | F5: delivered | G5: 2
A6: 2026-06-03 | B6: Mercado Livre | C6: Máscara Nasal Resmed Airfit N30i Apneia | D6: 480 | E6: Saúde/CPAP | F6: delivered | G6: 3
A7: 2026-06-01 | B7: Mercado Livre | C7: Macaco Hidráulico Tipo Jacaré 2ton Portátil | D7: 249.99 | E7: Ferramentas | F7: delivered | G7: 4
A8: 2026-05-30 | B8: iFood | C8: Pipa Sushi & Temakeria – 1x Monte Seu Poke | D8: 90.29 | E8: Delivery/Sushi | F8: delivered | G8: 5
A9: 2026-05-18 | B9: iFood | C9: Pipa Sushi & Temakeria – 1x Monte Seu Poke | D9: 67.31 | E9: Delivery/Sushi | F9: delivered | G9: 6
A10: 2026-05-16 | B10: iFood | C10: Maria Baunilha Confeitaria – 1x Trio Maria Baunilha | D10: 73.03 | E10: Delivery/Confeitaria | F10: delivered | G10: 7
A11: 2026-05-11 | B11: Mercado Livre | C11: Câmera Inteligente Im7 3mp De Resolução | D11: 429.9 | E11: Eletrônicos | F11: delivered | G11: 8
A12: 2026-05-11 | B12: iFood | C12: iFood (taxa/pedido) – - | D12: 7.95 | E12: Delivery/Taxa | F12: delivered | G12: 9
A13: 2026-05-09 | B13: Mercado Livre | C13: Sensor Presença Humana Radar Inteligente | D13: 379.98 | E13: Eletrônicos | F13: delivered | G13: 10
A14: 2026-05-03 | B14: Mercado Livre | C14: Prateleira Estilo Industrial Suporte Em Madeira | D14: 132 | E14: Casa | F14: delivered | G14: 11
A15: 2026-05-02 | B15: iFood | C15: Bianca Tolêdo Confeitaria – 1x Cake Moça e Morango + 1x Cake Cenoura | D15: — | E15: Delivery/Confeitaria | F15: delivered | G15: 12
A16: 2026-04-29 | B16: Mercado Livre | C16: Relógio Parede Digital Grande Calendário | D16: 105.99 | E16: Casa | F16: delivered | G16: 13
A17: 2026-04-27 | B17: Mercado Livre | C17: Álcool Isopropílico Quimivida 1l 99,8% | D17: 71.94 | E17: Higiene | F17: delivered | G17: 14
A18: 2026-04-27 | B18: iFood | C18: Bianca Tolêdo Confeitaria – 1x Promoção: 2 Cake in box | D18: — | E18: Delivery/Confeitaria | F18: delivered | G18: 15
A19: 2026-04-22 | B19: Mercado Livre | C19: Organizador De Fios E Cabos Baixo Mesa | D19: 36.9 | E19: Home Office | F19: delivered | G19: 16
A20: 2026-04-20 | B20: iFood | C20: Jurassic Pizza - Bessa – 1x Combo 1 - Pizza G + Refri 1l | D20: 74.88 | E20: Delivery/Pizza | F20: delivered | G20: 17
A21: 2026-04-17 | B21: Mercado Livre | C21: Kit Teste Ouro Pedra De Toque + Ácido 22k | D21: 69.9 | E21: Outros | F21: delivered | G21: 18
A22: 2026-04-16 | B22: Mercado Livre | C22: For I 2 Dispositivo De Ronco Elétrico | D22: 62.25 | E22: Saúde/CPAP | F22: delivered | G22: 19
A23: 2026-04-12 | B23: Mercado Livre | C23: Bravecto 4,5 A 10 Kg Antipulgas | D23: 162.9 | E23: Pet | F23: delivered | G23: 20
A24: 2026-04-05 | B24: Mercado Livre | C24: Antipulgas Bravecto Original De 20 A 40 Kg | D24: 440 | E24: Pet | F24: delivered | G24: 21
A25: 2026-04-03 | B25: iFood | C25: Matterello Pizza – 2x M (8 FATIAS) 2 SABORES | D25: — | E25: Delivery/Pizza | F25: delivered | G25: 22
A26: 2026-03-XX | B26: Mercado Livre | C26: 4 produtos Mercado Livre | D26: 824.5 | E26: Cancelado | F26: cancelled | G26: 23
A27: 2026-03-30 | B27: Mercado Livre | C27: Vittak Defletor Ar Condicionado Split | D27: 27.9 | E27: Casa | F27: delivered | G27: 24
A28: 2026-03-30 | B28: Mercado Livre | C28: Traqueia Cpap Pvc Cinza 22mm X 1,80m | D28: 49.9 | E28: Saúde/CPAP | F28: delivered | G28: 25
A29: 2026-03-29 | B29: Mercado Livre | C29: Lavadora De Alta Pressão Wap Premier 2600 | D29: 919 | E29: Casa | F29: delivered | G29: 26
A30: 2026-03-28 | B30: Mercado Livre | C30: Water Cooler Argb 240mm Pwm Para Cpu | D30: 399.99 | E30: Eletrônicos | F30: delivered | G30: 27
A31: 2026-03-27 | B31: Mercado Livre | C31: Tapete Protetor De Piso Cadeira Gamer | D31: 151.8 | E31: Home Office | F31: delivered | G31: 28
A32: 2026-03-25 | B32: Mercado Livre | C32: Electrolux Filtro/refil De Água Acqua Pure | D32: 69.9 | E32: Casa | F32: delivered | G32: 29
A33: 2026-03-25 | B33: Mercado Livre | C33: Luminária Led 3d De Mesa Logo Personalizada | D33: 137.86 | E33: Home Office | F33: delivered | G33: 30
A34: 2026-03-24 | B34: Mercado Livre | C34: Filtro De Café 51mm Não Pressurizado Inox | D34: 54.9 | E34: Casa | F34: delivered | G34: 31
A35: 2026-03-23 | B35: Mercado Livre | C35: Máquina De Gelo Turbo Ice Premium Mondial | D35: 699.9 | E35: Eletrodomésticos | F35: delivered | G35: 32
A36: 2026-03-22 | B36: Mercado Livre | C36: Relógio Digital Mesa Led Wooden Clock | D36: 49.83 | E36: Casa | F36: delivered | G36: 33
A37: 2026-03-22 | B37: Mercado Livre | C37: Desk Pad Mouse Pad 90x40 Extra Grande | D37: 41.24 | E37: Home Office | F37: delivered | G37: 34
... A66: 2026-02-12 | B66: Mercado Livre | C66: Máscara Nasal Airfit P30i P M G Resmed | D66: 482.55 | E66: Saúde/CPAP | F66: delivered | G66: 63
A67: 2026-01-28 | B67: iFood | C67: Maria Baunilha Confeitaria – 2x Copo da Felicidade | D67: — | E67: Delivery/Confeitaria | F67: delivered | G67: 64
A68: 2026-01-16 | B68: iFood | C68: Formaggio 43 - Forneria – 2x Pizza grande - até 02 sabores | D68: 191.8 | E68: Delivery/Pizza | F68: delivered | G68: 65
...
