Workbook

Sheet 00 COMMAND CENTER
B1: ◆ WEALTH MANAGEMENT COMMAND CENTER · Eduardo Forster Giovannini · 2026
B2: All KPI values live-linked from CALC sheet · Edit CALC col D format codes to change display globally · Jul 2026
B4: ◆ NET WORTH & LIQUIDITY
B5: EST NET WORTH | D5: TOTAL LIQUID | F5: IB NET DEPLOYED | H5: FUNDOS BRL | J5: CANCEL SAV/YR
B6: =CALC!E161 | D6: =CALC!E162 | F6: =CALC!E163 | H6: =CALC!E164 | J6: =CALC!E175
B8: ◆ CAPITAL FLOWS H1 2026
B9: FX OUTBOUND | D9: INBOUND | F9: AVG FX RATE | H9: IB DEPOSITS | J9: IB WITHDRAWAL
B10: =CALC!E165 | D10: =CALC!E166 | F10: =CALC!E167 | H10: =CALC!E168 | J10: =CALC!E169
B12: ◆ LIFESTYLE & SUBSCRIPTION STACK
B13: CARD SPEND H1 | D13: CARD AVG/MO | F13: PIX NET FLOW | H13: SUB STACK/MO | J13: CANCEL SAV/MO
B14: =CALC!E170 | D14: =CALC!E171 | F14: =CALC!E172 | H14: =CALC!E173 | J14: =CALC!E174
B16: ◆ MoM SIGNALS (Jun vs May 2026) — ▲=good ▼=bad (inverted for costs)
B17: Card Spend | D17: PIX In | F17: PIX Out | H17: FX Outbound | J17: Sub Stack
B18: =CALC!C488 | C18: =CALC!D488 | D18: =CALC!C489 | E18: =CALC!D489 | F18: =CALC!C490 | G18: =CALC!D490 | H18: =CALC!C491 | I18: =CALC!D491 | J18: =CALC!C493 | K18: =CALC!D493
B20: ◆ PRIORITY ACTIONS — live from 08 ALERTS
B21: # | C21: SEV | D21: DOMAIN | E21: FINDING | I21: EXPOSURE | J21: STATUS
B22: # | C22: Severity | D22: Domain | E22: Finding | I22: BRL Exposure | J22: Status
B23: 1 | C23: CRITICAL | D23: Subscriptions | E23: 4 services flagged CANCEL: Claude x2 (0/mo), Grok (R$14… | I23: — | J23: ⏳ Pending
B24: 2 | C24: CRITICAL | D24: FX Reconciliation | E24: R$652,789 sent to USA Own Account (67995 nature). Valid… | I24: 652788.61 | J24: ⏳ Pending
B25: 3 | C25: CRITICAL | D25: Subscription Stack Bloat | E25: R$0/mo in REVIEW = 3 services undecided. Annual exposur… | I25: — | J25: ⏳ Pending
B26: 4 | C26: HIGH | D26: Liquidity Concentration | E26: 100% of liquid assets in 2 digital banks (Inter + MP = … | I26: 23196.9 | J26: ⏳ Pending
B27: 5 | C27: HIGH | D27: IOF + FX Cost | E27: R$0 IOF paid on FX operations. R$0 total câmbio through… | I27: — | J27: ⏳ Pending
B28: 6 | C28: HIGH | D28: IB Withdrawal Unconfirmed | E28: R$19,196 IB withdrawal via Wise Jun/2026 (91992). Desti… | I28: 19195.81 | J28: ⏳ Pending
B29: 7 | C29: HIGH | D29: Lottery/Gambling Spend | E29: R$6,455 in Loteria charges on MP card 2026. No budget c… | I29: 6455.1 | J29: ⏳ Pending
B31: KPI tiles wired: 15 live → CALC · MoM arrows: 5 signals · Alerts: live → 08 ALERTS · Built Jul 2026

Sheet CALC
B1: CALC — Single Source of Truth · financas-2026 · Eduardo Forster Giovannini
B2: Built 2026-07-14 · All values sourced from financas2026-DataEntry.xlsx
B4: SECTION 1 · BANK BALANCES — Confirmed 13/Jul/2026
B5: Institution | C5: Balance (BRL) | D5: Prev Balance | E5: Type | F5: Confirmed | G5: Status
B6: Banco Inter | C6: 18934.67 | D6: 42112.59 | E6: Digital | F6: 13/Jul/2026 | G6: CONFIRMED
B7: Mercado Pago | C7: 4262.23 | D7: 10102.81 | E7: Digital | F7: 12/Jul/2026 | G7: CONFIRMED
B8: BB Brasil | C8: 0 | D8: 0 | E8: Checking | F8: 13/Jul/2026 | G8: CONFIRMED
B9: BCB Registrato | C9: 0 | D9: 0 | E9: Registry | F9: 29/Jun/2026 | G9: REGISTRY
B10: TOTAL LIQUID | C10: =SUM(C6:C9)
B12: SECTION 2 · FX OPERATIONS — BCB Câmbio · Jan–Jun 2026 (35 operations)
B13: Date | C13: Institution | D13: Destination | E13: FCY Amt | F13: BRL Amount | G13: CCY | H13: Direction | I13: FX Rate | J13: Nature
B14: 2026-01-26 | C14: Banco Topázio | D14: Interactive Brokers | E14: 200 | F14: 1071.22 | G14: USD | H14: IB Deposit | I14: 5.3561 | J14: 91992 IB deposit
B15: 2026-01-27 | C15: BB Brasil | D15: USA - Own Account | E15: 3000 | F15: 15886.01 | G15: USD | H15: Outbound | I15: 5.2953 | J15: 67995 Self-transfer
B16: 2026-01-30 | C16: BB Brasil | D16: USA - Own Account | E16: 3000 | F16: 16063.89 | G16: USD | H16: Outbound | I16: 5.3546 | J16: 67995 Self-transfer
B17: 2026-02-09 | C17: BB Brasil | D17: USA - Own Account | E17: 3000 | F17: 15868.79 | G17: USD | H17: Outbound | I17: 5.2896 | J17: 67995 Self-transfer
B18: 2026-02-11 | C18: BB Brasil | D18: USA - Own Account | E18: 3000 | F18: 15789.96 | G18: USD | H18: Outbound | I18: 5.2633 | J18: 67995 Self-transfer
B19: 2026-03-03 | C19: BB Brasil | D19: USA - Own Account | E19: 3000 | F19: 16024.35 | G19: USD | H19: Outbound | I19: 5.3414 | J19: 67995 Self-transfer
B20: 2026-03-13 | C20: BB Brasil | D20: USA - Own Account | E20: 3000 | F20: 15877.18 | G20: USD | H20: Outbound | I20: 5.2924 | J20: 67995 Self-transfer
B21: 2026-03-18 | C21: BB Brasil | D21: USA - Own Account | E21: 3000 | F21: 15963.15 | G21: USD | H21: Outbound | I21: 5.3211 | J21: 67995 Self-transfer
B22: 2026-04-22 | C22: BB Brasil | D22: USA - Own Account | E22: 3000 | F22: 15878.08 | G22: USD | H22: Outbound | I22: 5.2927 | J22: 67995 Self-transfer
B23: 2026-04-30 | C23: Banco Topázio | D23: Interactive Brokers | E23: 100 | F23: 503.62 | G23: USD | H23: IB Deposit | I23: 5.0362 | J23: 91992 IB deposit
B24: 2026-05-07 | C24: BB Brasil | D24: USA - Own Account | E24: 3000 | F24: 15132.89 | G24: USD | H24: Outbound | I24: 5.0443 | J24: 67995 Self-transfer
B25: 2026-05-07 | C25: Banco Inter | D25: USA - Own Account | E25: 5000 | F25: 24939.84 | G25: USD | H25: Outbound | I25: 4.988 | J25: 67995 Self-transfer via Inter
... B45: 2026-06-26 | C45: Wise Brasil | D45: Interactive Brokers | E45: 3834.82 | F45: 19195.81 | G45: USD | H45: IB Withdraw | I45: 5.1783 | J45: 91992 IB withdrawal via Wise
B46: ──── 2024 Historical Travel FX (context only) ──── | E46: 0 | F46: 0 | I46: 0
B47: 2024-08-27 | C47: Daycoval | D47: Switzerland Travel | E47: 800 | F47: 5618.2 | G47: CHF | H47: Travel FX | I47: 7.0228 | J47: 32999 Travel
B48: 2024-08-27 | C48: Daycoval | D48: USA Travel | E48: 2000 | F48: 11473.79 | G48: USD | H48: Travel FX | I48: 5.7369 | J48: 32999 Travel
B49: 2024-11-19 | C49: Daycoval | D49: Switzerland Travel | E49: 1500 | F49: 10534.12 | G49: CHF | H49: Travel FX | I49: 7.0228 | J49: 32999 Travel
B50: OUTBOUND 2026 | E50: 0 | F50: 0 | I50: 0
B51: INBOUND 2026 | E51: 0 | F51: 0 | I51: 0
B53: FX DIRECTION SUMMARY
B54: Direction | C54: Count | D54: BRL Total | E54: FCY Total | F54: Avg Rate
B55: Fund Deposit | C55: 3 | D55: 175765.83 | E55: 0
B56: IB Deposit | C56: 7 | D56: 197706.57 | E56: 38801.24 | F56: 5.1210429
B57: IB Withdraw | C57: 1 | D57: 19195.81 | E57: 3834.82 | F57: 5.1783
B58: Inbound | C58: 2 | D58: 98857 | E58: 0
B59: Outbound | C59: 19 | D59: 652788.61 | E59: 126279.38 | F59: 5.1799263
B60: Travel FX | C60: 3 | D60: 27626.11 | E60: 4300 | F60: 6.5941667
B61: Unknown | C61: 3 | D61: 0 | E61: 0
B63: SECTION 3 · MP FATURAS MONTHLY SUMMARY — 146 Transactions
...

Sheet 01 NET WORTH
B1: BALANCE SHEET · Eduardo Forster Giovannini · Jul 2026
B3: LIQUID ASSETS
B4: Institution | C4: Type | D4: Balance (R$) | E4: Confirmed | F4: Notes | G4: Status
B5: Banco Inter | C5: Digital | D5: 18934.67 | E5: 13/Jul/2026 | F5: Conta 6627102 · R$18,922 disponível + R$12,60 bloqueado | G5: ✅ Confirmed
B6: Mercado Pago | C6: Digital | D6: 4262.23 | E6: 12/Jul/2026 | F6: Extrato MP PDF 01–12/Jul/2026 | G6: ✅ Confirmed
B7: BB Brasil | C7: Checking | D7: 0 | E7: 13/Jul/2026 | F7: Rende Fácil not in export | G7: ✅ Confirmed
B8: BCB Registrato | C8: Registry | D8: 0 | E8: 29/Jun/2026 | F8: CCS registry only — no cash balance | G8: ℹ Registry
B9: TOTAL LIQUID → R$ 23,196.90
B11: INVESTMENT ASSETS (Capital Deployed)
B12: Instrument | C12: Currency | D12: BRL Equiv. | E12: Period | F12: Notes | G12: Status
B13: Interactive Brokers — Net Deposits | C13: USD | D13: 197706.57 | E13: Jan–Jun 2026 | F13: 8 deposit operations via Topázio + Wise | G13: 📈 Deployed
B14: IB Withdrawal (returned) | C14: USD | D14: -19195.81 | E14: Jun 2026 | F14: R$19,195 returned via Wise — confirm destination | G14: ⚠ Verify
B15: Fundos BRL — Topázio | C15: BRL | D15: 175765.83 | E15: May–Jun 2026 | F15: 3 deposits: R$45k + R$78k + R$52k | G15: 📈 Deployed
B16: TOTAL INVESTMENTS → R$ 335,080.78
B18: FX OUTFLOWS — Self-Transfers to USA (Own Account)
B19: Date | C19: Institution | D19: USD Sent | E19: BRL Cost | F19: FX Rate | G19: Notes
B20: 46049 | C20: BB Brasil | D20: 3000 | E20: 15886.01 | F20: 5.2953 | G20: 67995 Self-transfer
B21: 46052 | C21: BB Brasil | D21: 3000 | E21: 16063.89 | F21: 5.3546 | G21: 67995 Self-transfer
B22: 46062 | C22: BB Brasil | D22: 3000 | E22: 15868.79 | F22: 5.2896 | G22: 67995 Self-transfer
B23: 46064 | C23: BB Brasil | D23: 3000 | E23: 15789.96 | F23: 5.2633 | G23: 67995 Self-transfer
B24: 46084 | C24: BB Brasil | D24: 3000 | E24: 16024.35 | F24: 5.3414 | G24: 67995 Self-transfer
B25: 46094 | C25: BB Brasil | D25: 3000 | E25: 15877.18 | F25: 5.2924 | G25: 67995 Self-transfer
B26: 46099 | C26: BB Brasil | D26: 3000 | E26: 15963.15 | F26: 5.3211 | G26: 67995 Self-transfer
B27: 46134 | C27: BB Brasil | D27: 3000 | E27: 15878.08 | F27: 5.2927 | G27: 67995 Self-transfer
B28: 46149 | C28: BB Brasil | D28: 3000 | E28: 15132.89 | F28: 5.0443 | G28: 67995 Self-transfer
B29: 46149 | C29: Banco Inter | D29: 5000 | E29: 24939.84 | F29: 4.988 | G29: 67995 Self-transfer via Inter
B30: 46153 | C30: Banco Inter | D30: 15000 | E30: 74340.4 | F30: 4.956 | G30: 67995 Self-transfer via Inter
B31: 46157 | C31: BB Brasil | D31: 500 | E31: 2577.87 | F31: 5.1558 | G31: 67995 Self-transfer
... B38: 46195 | C38: Wise Brasil | D38: 17000 | E38: 87442.26 | F38: 5.1436 | G38: 67995 Wise UK
B39: TOTAL USD OUTBOUND → USD 126,279 · R$ 652,788.61
B41: ESTIMATED NET WORTH
B42: Liquid Assets | D42: 23196.9
B43: Investment Assets (net) | D43: 335080.78
B44: ESTIMATED NET WORTH | D44: 358277.68

Sheet 02 CAPITAL FLOWS
B1: CAPITAL FLOWS · Jan–Jun 2026 · All Sources Unified
B3: MONTHLY CASH FLOW SUMMARY
B4: Month | C4: Card Spend | D4: PIX In | E4: PIX Out | F4: FX Out | G4: FX In | H4: IOF | I4: Net Flow
B5: 2026-01 | C5: 3745.4 | D5: 0 | E5: 0 | F5: 0 | G5: 0 | H5: 0 | I5: -3745.4
B6: 2026-02 | C6: 9515.9 | D6: 40000 | E6: 0 | F6: 0 | G6: 0 | H6: 0 | I6: 30484.1
B7: 2026-03 | C7: 14231.47 | D7: 0 | E7: 11432.41 | F7: 0 | G7: 0 | H7: 0 | I7: -25663.88
B8: 2026-04 | C8: 5330.44 | D8: 40000 | E8: 10330 | F8: 0 | G8: 0 | H8: 0 | I8: 24339.56
B9: 2026-05 | C9: 3308.38 | D9: 115000 | E9: 69919.97 | F9: 0 | G9: 0 | H9: 0 | I9: 41771.65
B10: 2026-06 | C10: 1114.17 | D10: 42010 | E10: 480 | F10: 0 | G10: 98857 | H10: 0 | I10: 139272.83
B13: TRANSACTION LOG — All Unified Movements
B14: Date | C14: Source | D14: Type | E14: Description | F14: BRL Amount | G14: CCY | H14: FX Rate | I14: Notes
B15: 45531 | C15: Daycoval | D15: Travel FX | E15: Switzerland Travel | F15: 5618.2 | G15: CHF | H15: 7.0228 | I15: 32999 Travel
B16: 45531 | C16: Daycoval | D16: Travel FX | E16: USA Travel | F16: 11473.79 | G16: USD | H16: 5.7369 | I16: 32999 Travel
B17: 45615 | C17: Daycoval | D17: Travel FX | E17: Switzerland Travel | F17: 10534.12 | G17: CHF | H17: 7.0228 | I17: 32999 Travel
B18: 46028 | C18: MP Cartão | D18: Delivery/iFood | E18: IFD*PIZZA NOW INTERMARES | F18: -173.79 | G18: BRL | I18: Fatura 2026-02
B19: 46030 | C19: MP Cartão | D19: IA/Tecnologia | E19: Compra internacional em OPENAI *CHATGPT SUBSCR | F19: -111.58 | G19: BRL | I19: Fatura 2026-02
B20: 46030 | C20: MP Cartão | D20: Assinatura | E20: APPLE.COM/BILL | F20: -21.9 | G20: BRL | I20: Fatura 2026-02
B21: 46032 | C21: MP Cartão | D21: Delivery/iFood | E21: IFD*34531468 EDWIN LEI | F21: -111.6 | G21: BRL | I21: Fatura 2026-02
B22: 46032 | C22: MP Cartão | D22: Assinatura | E22: APPLE.COM/BILL | F22: -19.9 | G22: BRL | I22: Fatura 2026-02
B23: 46035 | C23: MP Cartão | D23: Outros | E23: MP*EDUARDOGIOVAN | F23: -0.78 | G23: BRL | I23: Fatura 2026-02
B24: 46036 | C24: MP Cartão | D24: IA/Tecnologia | E24: Compra internacional em MANUS AI | F24: -25.79 | G24: BRL | I24: Fatura 2026-02
B25: 46037 | C25: MP Cartão | D25: Internet | E25: DL*Starlink Braz | F25: -235.52 | G25: BRL | I25: Fatura 2026-02
B26: 46038 | C26: MP Cartão | D26: Loteria | E26: MP*LOTERIASONLINEU1AQ | F26: -143.6 | G26: BRL | I26: Fatura 2026-02
B27: 46038 | C27: MP Cartão | D27: Delivery/iFood | E27: IFD*FORMAGGIO RESTAURANTE | F27: -191.8 | G27: BRL | I27: Fatura 2026-02
B28: 46039 | C28: MP Cartão | D28: IA/Tecnologia | E28: Compra internacional em OPENAI *CHATGPT SUBSCR | F28: -111.37 | G28: BRL | I28: Fatura 2026-02
B29: 46039 | C29: MP Cartão | D29: Loteria | E29: MP*LOTERIASONLINE542V | F29: -111 | G29: BRL | I29: Fatura 2026-02
... B32: 46043 | C32: MP Cartão | D32: IA/Tecnologia | E32: Compra internacional em MANUS AI | F32: -556.83 | G32: BRL | I32: Fatura 2026-02
B33: 46048 | C33: Banco Topázio | D33: IB Deposit | E33: Interactive Brokers | F33: 1071.22 | G33: USD | H33: 5.3561 | I33: 91992 IB deposit
B34: 46049 | C34: MP Cartão | D34: Outros | E34: Compra internacional em RAYCAST.COM | F34: -524.63 | G34: BRL | I34: Fatura 2026-02
B35: 46049 | C35: BB Brasil | D35: Outbound | E35: USA - Own Account | F35: -15886.01 | G35: USD | H35: 5.2953 | I35: 67995 Self-transfer
B36: 46050 | C36: MP Cartão | D36: Delivery/iFood | E36: IFD*34531468 EDWIN LEI | F36: -55.8 | G36: BRL | I36: Fatura 2026-02
B37: 46052 | C37: MP Cartão | D37: Assinatura | E37: APPLE.COM/BILL | F37: -99.9 | G37: BRL | I37: Fatura 2026-02
B38: 46052 | C38: BB Brasil | D38: Outbound | E38: USA - Own Account | F38: -16063.89 | G38: USD | H38: 5.3546 | I38: 67995 Self-transfer
B39: 46056 | C39: MP Cartão | D39: Outros | E39: Compra internacional em DESKTOP COMMANDER | F39: -272.21 | G39: BRL | I39: Fatura 2026-02
B40: 46057 | C40: MP Cartão | D40: Loteria | E40: MP*LOTERIASONLINEM4UQ | F40: -168 | G40: BRL | I40: Fatura 2026-02
B41: 46058 | C41: MP Cartão | D41: Loteria | E41: MP*LOTERIASONLINEYY48 | F41: -84 | G41: BRL | I41: Fatura 2026-02
B42: 46058 | C42: MP Cartão | D42: IA/Tecnologia | E42: Compra internacional em OPENAI *CHATGPT SUBSCR | F42: -108.89 | G42: BRL | I42: Fatura 2026-03
B43: 46061 | C43: MP Cartão | D43: Assinatura | E43: APPLECOMBILL | F43: -21.9 | G43: BRL | I43: Fatura 2026-03
B44: 46062 | C44: MP Cartão | D44: Loteria | E44: MP*LOTERIASONLINEBFN5 | F44: -150 | G44: BRL | I44: Fatura 2026-03
B45: 46062 | C45: BB Brasil | D45: Outbound | E45: USA - Own Account | F45: -15868.79 | G45: USD | H45: 5.2896 | I45: 67995 Self-transfer
...

Sheet 03 INTERNATIONAL
B1: INTERNATIONAL CAPITAL OPERATIONS · BCB Câmbio Register · Jan–Jun 2026
B3: SUMMARY
B4: FX Outbound | D4: IB Deposits | F4: Fund Capital | H4: Inbound | J4: IB Withdrawal
B5: 652788.61 | D5: 197706.57 | F5: 175765.83 | H5: 98857 | J5: 19195.81
B7: BY DIRECTION
B8: Direction | C8: Count | D8: BRL Total | E8: USD Total | F8: Avg Rate | G8: % of Outflow | H8: Institutions
B9: Outbound | C9: 19 | D9: 652788.61 | E9: 126279.38 | F9: 5.1799263 | G9: 0.60833007 | H9: BB Brasil, Banco Inter, Wise Brasil
B10: IB Deposit | C10: 7 | D10: 197706.57 | E10: 38801.24 | F10: 5.1210429 | G10: 0.18424165 | H10: Banco Topázio, Wise Brasil
B11: Fund Deposit | C11: 3 | D11: 175765.83 | E11: 0 | F11: 0 | G11: 0.1637952 | H11: Banco Topázio
B12: Inbound | C12: 2 | D12: 98857 | E12: 0 | F12: 0 | G12: 0 | H12: BB Brasil, Ouribank
B13: Travel FX | C13: 3 | D13: 27626.11 | E13: 4300 | F13: 6.5941667 | G13: 0.025744618 | H13: Daycoval
B14: IB Withdraw | C14: 1 | D14: 19195.81 | E14: 3834.82 | F14: 5.1783 | G14: 0.017888468 | H14: Wise Brasil
B17: FULL OPERATIONS LOG (32 operations)
B18: Date | C18: Institution | D18: Destination | E18: FCY | F18: BRL | G18: CCY | H18: Direction | I18: Rate | J18: Nature
B19: 46048 | C19: Banco Topázio | D19: Interactive Brokers | E19: 200 | F19: 1071.22 | G19: USD | H19: IB Deposit | I19: 5.3561 | J19: 91992 IB deposit
B20: 46049 | C20: BB Brasil | D20: USA - Own Account | E20: 3000 | F20: 15886.01 | G20: USD | H20: Outbound | I20: 5.2953 | J20: 67995 Self-transfer
B21: 46052 | C21: BB Brasil | D21: USA - Own Account | E21: 3000 | F21: 16063.89 | G21: USD | H21: Outbound | I21: 5.3546 | J21: 67995 Self-transfer
B22: 46062 | C22: BB Brasil | D22: USA - Own Account | E22: 3000 | F22: 15868.79 | G22: USD | H22: Outbound | I22: 5.2896 | J22: 67995 Self-transfer
B23: 46064 | C23: BB Brasil | D23: USA - Own Account | E23: 3000 | F23: 15789.96 | G23: USD | H23: Outbound | I23: 5.2633 | J23: 67995 Self-transfer
B24: 46084 | C24: BB Brasil | D24: USA - Own Account | E24: 3000 | F24: 16024.35 | G24: USD | H24: Outbound | I24: 5.3414 | J24: 67995 Self-transfer
B25: 46094 | C25: BB Brasil | D25: USA - Own Account | E25: 3000 | F25: 15877.18 | G25: USD | H25: Outbound | I25: 5.2924 | J25: 67995 Self-transfer
B26: 46099 | C26: BB Brasil | D26: USA - Own Account | E26: 3000 | F26: 15963.15 | G26: USD | H26: Outbound | I26: 5.3211 | J26: 67995 Self-transfer
B27: 46134 | C27: BB Brasil | D27: USA - Own Account | E27: 3000 | F27: 15878.08 | G27: USD | H27: Outbound | I27: 5.2927 | J27: 67995 Self-transfer
B28: 46142 | C28: Banco Topázio | D28: Interactive Brokers | E28: 100 | F28: 503.62 | G28: USD | H28: IB Deposit | I28: 5.0362 | J28: 91992 IB deposit
B29: 46149 | C29: BB Brasil | D29: USA - Own Account | E29: 3000 | F29: 15132.89 | G29: USD | H29: Outbound | I29: 5.0443 | J29: 67995 Self-transfer
B30: 46149 | C30: Banco Inter | D30: USA - Own Account | E30: 5000 | F30: 24939.84 | G30: USD | H30: Outbound | I30: 4.988 | J30: 67995 Self-transfer via Inter
... B53: 45615 | C53: Daycoval | D53: Switzerland Travel | E53: 1500 | F53: 10534.12 | G53: CHF | H53: Travel FX | I53: 7.0228 | J53: 32999 Travel

Sheet 04 PORTFOLIO
B1: PORTFOLIO · Investment Deployment · Interactive Brokers + Fundos BRL
B3: INTERACTIVE BROKERS — DEPOSIT TIMELINE
B4: Date | C4: Institution | D4: USD Amount | E4: BRL Cost | F4: FX Rate | G4: Notes
B5: 46048 | C5: Banco Topázio | D5: 200 | E5: 1071.22 | F5: 5.3561 | G5: 91992 IB deposit
B6: 46142 | C6: Banco Topázio | D6: 100 | E6: 503.62 | F6: 5.0362 | G6: 91992 IB deposit
B7: 46160 | C7: Wise Brasil | D7: 3834.82 | E7: 19195.81 | F7: 5.0056 | G7: 91992 IB via Wise
B8: 46161 | C8: Banco Topázio | D8: 1000 | E8: 5114.85 | F8: 5.1149 | G8: 91992 IB deposit
B9: 46162 | C9: Banco Topázio | D9: 6212.32 | E9: 31651.83 | F9: 5.0949 | G9: 91992 IB deposit
B10: 46170 | C10: Banco Topázio | D10: 20000 | E10: 101772.38 | F10: 5.0886 | G10: 91992 IB deposit
B11: 46195 | C11: Wise Brasil | D11: 7454.1 | E11: 38396.86 | F11: 5.151 | G11: 91992 IB via Wise
B12: 46199 | C12: Wise Brasil | D12: 3834.82 | E12: 19195.81 | F12: 5.1783 | G12: 91992 IB withdrawal via Wise
B13: IB TOTAL → USD 42,636.06 · R$ 216,902.38
B15: FUNDOS BRL — CAPITAL DEPLOYMENTS
B16: Date | C16: Institution | D16: Destination | E16: BRL Deployed | F16: CCY | G16: Notes
B17: 46164 | C17: Banco Topázio | D17: Fundos investimento BRL | E17: 45000 | F17: BRL | G17: 67043 Fund capital
B18: 46178 | C18: Banco Topázio | D18: Fundos investimento BRL | E18: 78323.92 | F18: BRL | G18: 67043 Fund capital
B19: 46192 | C19: Banco Topázio | D19: Fundos investimento BRL | E19: 52441.91 | F19: BRL | G19: 67043 Fund capital
B20: FUNDS TOTAL → R$ 175,765.83
B21: COMBINED DEPLOYMENT → R$ 373,472.40 (IB + Funds)

Sheet 05 LIFESTYLE
B1: LIFESTYLE & BURN RATE · Card + ML + iFood · Jan–Jun 2026
B3: CARD SPEND | D3: AVG/MONTH | F3: ML+iFOOD
B4: 37245.76 | D4: 6207.6267 | F4: 27488.73
B7: CARD SPEND BY CATEGORY
B8: Category | C8: Total (R$) | D8: % of Card | E8: Avg/Month | F8: Txs | G8: Classification
B9: Viagem | C9: 9036.83 | D9: 0.24262708 | E9: 1506.1383 | F9: 1 | G9: 💡 Discretionary
B10: Compras/ML | C10: 8744.68 | D10: 0.23478323 | E10: 1457.4467 | F10: 9 | G10: 💡 Discretionary
B11: IA/Tecnologia | C11: 6624.36 | D11: 0.17785541 | E11: 1104.06 | F11: 37 | G11: ⚠ Review
B12: Loteria | C12: 6455.1 | D12: 0.173311 | E12: 1075.85 | F12: 39 | G12: ⚠ Review
B13: Outros | C13: 2235.58 | D13: 0.060022403 | E13: 372.59667 | F13: 9 | G13: 💡 Discretionary
B14: Internet | C14: 1413.12 | D14: 0.037940426 | E14: 235.52 | F14: 6 | G14: ✅ Essential
B15: Assinatura | C15: 1227.5 | D15: 0.032956771 | E15: 204.58333 | F15: 19 | G15: 💡 Discretionary
B16: Delivery/iFood | C16: 1217.92 | D16: 0.032699561 | E16: 202.98667 | F16: 14 | G16: ✅ Essential
B17: Transporte | C17: 205.34 | D17: 0.0055131108 | E17: 34.223333 | F17: 10 | G17: 💡 Discretionary
B18: Telecomunicações | C18: 74.43 | D18: 0.0019983483 | E18: 12.405 | F18: 1 | G18: ✅ Essential
B19: Digital | C19: 10.9 | D19: 0.00029265076 | E19: 1.8166667 | F19: 1 | G19: 💡 Discretionary
B22: MONTHLY CARD SPEND
B23: Month | C23: Card Spend | D23: Txs | E23: vs Avg | F23: vs Prior | G23: Notes
B24: 2026-01 | C24: 3745.4 | D24: 18 | E24: -2462.2267 | F24: 0
B25: 2026-02 | C25: 9515.9 | D25: 21 | E25: 3308.2733 | F25: 5770.5
B26: 2026-03 | C26: 14231.47 | D26: 32 | E26: 8023.8433 | F26: 4715.57
B27: 2026-04 | C27: 5330.44 | D27: 33 | E27: -877.18667 | F27: -8901.03
B28: 2026-05 | C28: 3308.38 | D28: 29 | E28: -2899.2467 | F28: -2022.06
B29: 2026-06 | C29: 1114.17 | D29: 13 | E29: -5093.4567 | F29: -2194.21
B32: MERCADO LIVRE + iFOOD ORDERS
B33: Date | C33: Platform | D33: Item | E33: Amount | F33: Category | G33: Status
B34: 2026-06-16 | C34: Mercado Livre | D34: Suporte Monitor Articulado Portátil Dobrável | E34: 144 | F34: Home Office | G34: delivered
B35: 2026-06-08 | C35: Mercado Livre | D35: Filtro De Ar Descartável Cpap Airmini Resmed | E35: 41.65 | F35: Saúde/CPAP | G35: delivered
B36: 2026-06-03 | C36: Mercado Livre | D36: Máscara Nasal Resmed Airfit N30i Apneia | E36: 480 | F36: Saúde/CPAP | G36: delivered
B37: 2026-06-01 | C37: Mercado Livre | D37: Macaco Hidráulico Tipo Jacaré 2ton Portátil | E37: 249.99 | F37: Ferramentas | G37: delivered
B38: 2026-05-30 | C38: iFood | D38: Pipa Sushi & Temakeria – 1x Monte Seu Poke | E38: 90.29 | F38: Delivery/Sushi | G38: delivered
B39: 2026-05-18 | C39: iFood | D39: Pipa Sushi & Temakeria – 1x Monte Seu Poke | E39: 67.31 | F39: Delivery/Sushi | G39: delivered
B40: 2026-05-16 | C40: iFood | D40: Maria Baunilha Confeitaria – 1x Trio Maria Baunilha | E40: 73.03 | F40: Delivery/Confeitaria | G40: delivered
B41: 2026-05-11 | C41: Mercado Livre | D41: Câmera Inteligente Im7 3mp De Resolução | E41: 429.9 | F41: Eletrônicos | G41: delivered
B42: 2026-05-11 | C42: iFood | D42: iFood (taxa/pedido) – - | E42: 7.95 | F42: Delivery/Taxa | G42: delivered
B43: 2026-05-09 | C43: Mercado Livre | D43: Sensor Presença Humana Radar Inteligente | E43: 379.98 | F43: Eletrônicos | G43: delivered
B44: 2026-05-03 | C44: Mercado Livre | D44: Prateleira Estilo Industrial Suporte Em Madeira | E44: 132 | F44: Casa | G44: delivered
B45: 2026-05-02 | C45: iFood | D45: Bianca Tolêdo Confeitaria – 1x Cake Moça e Morango + 1x Cake Cenoura | E45: 0 | F45: Delivery/Confeitaria | G45: delivered
... B102: 2026-01-03 | C102: Mercado Livre | D102: Kit Cabo+espelho Odontológico Inox | E102: 21.85 | F102: Saúde/Higiene | G102: delivered

Sheet 06 SUBSCRIPTION MGR
B1: SUBSCRIPTION MANAGER · Stack Audit · KEEP / CANCEL / REVIEW
B3: TOTAL/MONTH | D3: KEEP/MONTH | F3: CANCEL SAVINGS | H3: CANCEL / YEAR
B4: 0 | D4: 0 | F4: 0 | H4: 0
B7: FULL SUBSCRIPTION REGISTER
B8: Source | C8: Service | D8: Plan | E8: CCY | F8: Mthly BRL | G8: Category | H8: Dup Risk | I8: Decision | J8: Annual BRL
C9: Direct AI | D9: automacao.giovannini@gmail.com | E9: Pro | F9: 0 | G9: 92 | H9: AI - General/Coding | I9: HIGH | J9: 0
C10: Direct AI | D10: cadastros.online1979@gmail.com | E10: Pro | F10: 0 | G10: 92 | H10: AI - General/Coding | I10: HIGH | J10: 0
C11: Direct AI | D11: giovannini.eduardo@gmail.com | E11: Plus | F11: 0 | G11: 106 | H11: AI - General Assistant | I11: MEDIUM | J11: 0
C12: Direct AI | D12: cadastros.online1979@gmail.com | E12: Pro | F12: 0 | G12: 96.99 | H12: AI - General/Workspace | I12: HIGH | J12: 0
C13: Direct AI | D13: cadastro.giovannini@gmail.com | E13: Unknown / credits | F13: 0 | H13: AI - Agent/Credits | I13: UNKNOWN | J13: 0
C14: Direct AI | D14: automacao.giovannini@gmail.com | E14: Unknown / credits | F14: 0 | G14: 418.43 | H14: AI - Agent/Credits | I14: UNKNOWN | J14: 0
C15: Direct AI | D15: giovannini.eduardo@gmail.com | E15: Pro | F15: 0 | G15: 106 | H15: AI - Coding Assistant | I15: MEDIUM | J15: 0
C16: Direct AI | D16: automacao.giovannini@gmail.com | E16: Unlimited | F16: 0 | G16: 45.37 | H16: AI - Desktop Automation | I16: UNKNOWN | J16: 0
C17: Apple | D17: Unknown | E17: Annual Subscription | F17: 0 | G17: 15.40833333333333 | H17: Creative/Productivity | I17: LOW | J17: 0
C18: Apple | D18: Unknown | E18: SuperGrok | F18: 0 | G18: 149.9 | H18: AI - General/Media | I18: HIGH | J18: 0
C19: Apple | D19: Unknown | E19: 200 GB storage | F19: 0 | G19: 19.9 | H19: Cloud/Storage | I19: LOW | J19: 0
C20: Apple | D20: Unknown | E20: Personal | F20: 0 | G20: 42.41666666666666 | H20: Productivity/Cloud | I20: MEDIUM | J20: 0
C21: Apple | D21: Unknown | E21: Auto-renewable Subscription | F21: 0 | G21: 28.325 | H21: Security/VPN | I21: LOW | J21: 0
C22: Apple | D22: Unknown | E22: Perplexity Pro for Mac | F22: 0 | G22: 99.9 | H22: AI - Research Assistant | I22: HIGH | J22: 0
C23: Apple | D23: Unknown | E23: TuneIn Premium | F23: 0 | G23: 31.9 | H23: Entertainment | I23: LOW | J23: 0
C24: KEEP TOTAL/MONTH | E24: BRL | F24: 0 | I24: REVIEW | J24: 0
C25: CANCEL SAVINGS/MONTH | E25: BRL | F25: 0 | I25: REVIEW | J25: 0
C26: REVIEW TOTAL/MONTH | E26: BRL | F26: 0 | I26: REVIEW | J26: 0
B29: DECISION SUMMARY
B30: KEEP/month | D30: CANCEL/month | F30: REVIEW/month | H30: TOTAL/month
B31: 0 | D31: 0 | F31: 0 | H31: 0

Sheet 07 CASH BRIDGE
B1: CASH BRIDGE · Banco Inter Account 6627102 · PIX + FX Reconciliation
B3: PIX IN | D3: PIX OUT | F3: NET PIX
B4: 237010 | D4: 92162.38 | F4: 144847.62
B7: FX/CÂMBIO OUT | D7: IOF PAID | F7: FINAL BALANCE
B8: 0 | D8: 0 | F8: 18934.67
B11: MOVEMENT LOG
B12: Date | C12: Type | D12: Description | E12: PIX (R$) | F12: FX (R$) | G12: IOF (R$)
B13: 46201 | C13: PIX In | D13: Eduardo Forster Giovannini | E13: 2000
B14: 46201 | C14: PIX In | D14: Eduardo F Giovannini | E14: 40000
B15: 46198 | C15: PIX In | D15: Eduardo F Giovannini | E15: 10
B16: 46178 | C16: PIX Out | D16: Eduardo Silva Dos Santos | E16: -480
B17: 46170 | C17: PIX Out | D17: Eduardo Silva Dos Santos | E17: -450
B18: 46167 | C18: PIX Out | D18: Eduardo Silva Dos Santos | E18: -470
B19: 46166 | C19: PIX Out | D19: Moacir Jose De Morais Filho | E19: -700
B20: 46164 | C20: PIX Out | D20: Lucas Rique Chaves Bezerra | E20: -1500
B21: 46164 | C21: PIX Out | D21: Lucas Rique Chaves Bezerra | E21: -500
B22: 46164 | C22: PIX Out | D22: Sbct Tech Solutions Llc | E22: -45000
B23: 46160 | C23: PIX In | D23: Eduardo F Giovannini | E23: 35000
B24: 46160 | C24: PIX Out | D24: Eduardo Giovannini | E24: -20000
... B38: 46064 | C38: PIX In | D38: Eduardo F Giovannini | E38: 40000

Sheet 08 ALERTS
B1: RISK & ACTION REGISTER · Wealth Management · Q3 2026
B3: # | C3: Severity | D3: Domain | E3: Finding | F3: BRL Exposure | G3: Recommended Action | H3: Status
B4: 1 | C4: CRITICAL | D4: Subscriptions | E4: 4 services flagged CANCEL: Claude x2 (0/mo), Grok (R$149.90/mo), TuneIn (R$31.90/mo). Total savings: R$0/mo · R$0/yr | G4: Cancel all 4 before next billing cycle. Verify via Apple Subscriptions + app accounts | H4: ⏳ Pending
B5: 2 | C5: CRITICAL | D5: FX Reconciliation | E5: R$652,789 sent to USA Own Account (67995 nature). Validate balances in USD account vs BCB records. 22 operations Jan–Jun | F5: 652788.61 | G5: Pull USD account statement. Reconcile every BCB operation against account balance | H5: ⏳ Pending
B6: 3 | C6: CRITICAL | D6: Subscription Stack Bloat | E6: R$0/mo in REVIEW = 3 services undecided. Annual exposure R$0 | G6: Audit each REVIEW service this week. Set KEEP/CANCEL decision. Target: eliminate ≥3 | H6: ⏳ Pending
B7: 4 | C7: HIGH | D7: Liquidity Concentration | E7: 100% of liquid assets in 2 digital banks (Inter + MP = R$23,197). BB balance R$0 | F7: 23196.9 | G7: Maintain R$30k+ buffer. Consider distributing across BB (Rende Fácil) and Inter | H7: ⏳ Pending
B8: 5 | C8: HIGH | D8: IOF + FX Cost | E8: R$0 IOF paid on FX operations. R$0 total câmbio through Inter | G8: Review IOF rate applied per operation. Compare institutions (Wise vs Topázio vs BB) | H8: ⏳ Pending
B9: 6 | C9: HIGH | D9: IB Withdrawal Unconfirmed | E9: R$19,196 IB withdrawal via Wise Jun/2026 (91992). Destination unconfirmed | F9: 19195.81 | G9: Confirm whether funds returned to Inter checking or redeployed in IB | H9: ⏳ Pending
B10: 7 | C10: HIGH | D10: Lottery/Gambling Spend | E10: R$6,455 in Loteria charges on MP card 2026. No budget cap set | F10: 6455.1 | G10: Set monthly Loteria limit (e.g. R$500). Remove from card if over limit | H10: ⏳ Pending
B11: 8 | C11: MEDIUM | D11: AI/Tech Card Overlap | E11: R$6,624 charged via card on IA/Tech. Likely duplicates subscription stack | F11: 6624.36 | G11: Cross-match card IA charges vs subscription list. Consolidate to single billing method | H11: ⏳ Pending
B12: 9 | C12: MEDIUM | D12: Travel/Viagem Spend | E12: R$9,037 in travel charges. Review vs business vs personal | F12: 9036.83 | G12: Classify each travel expense: business vs personal. Flag deductible items | H12: ⏳ Pending
B13: 10 | C13: MEDIUM | D13: ML Compras Volume | E13: R$31,570 in Mercado Livre purchases (69 items). Strong Home Office + CPAP pattern | F13: 31570.45 | G13: Tag each purchase as CAPEX (equipment), HEALTH, or CONSUMABLE for tax/tracking | H13: ⏳ Pending
B14: 11 | C14: LOW | D14: Wise Brasil Activity | E14: Multiple Wise operations detected (IB deposits + UK transfers). Ensure all reported in BACEN | G14: Confirm Wise BACEN reporting compliance. Keep KYC documentation current | H14: ✅ Monitor
B15: 12 | C15: LOW | D15: SBCT Tech Solutions (USA) | E15: R$45,000 PIX Out to SBCT Tech Solutions LLC (USA company) via Inter May/2026 | F15: 45000 | G15: Confirm nature of payment: service invoice? investment? Ensure documentation | H15: ⏳ Pending

Sheet _DATA
A1: Month | B1: Card Spend | D1: Category | E1: Total | G1: Direction | H1: BRL | J1: Decision | K1: Monthly BRL
A2: 2026-01 | B2: 3745.4 | D2: Viagem | E2: 9036.83 | G2: FX Outbound | H2: 652788.61 | J2: KEEP | K2: 0
A3: 2026-02 | B3: 9515.9 | D3: Compras/ML | E3: 8744.68 | G3: IB Deposits | H3: 197706.57 | J3: CANCEL | K3: 0
A4: 2026-03 | B4: 14231.47 | D4: IA/Tecnologia | E4: 6624.36 | G4: Fund Capital | H4: 175765.83 | J4: REVIEW | K4: 0
A5: 2026-04 | B5: 5330.44 | D5: Loteria | E5: 6455.1 | G5: Inbound | H5: 98857
A6: 2026-05 | B6: 3308.38 | D6: Outros | E6: 2235.58 | G6: IB Withdraw | H6: 19195.81
A7: 2026-06 | B7: 1114.17 | D7: Internet | E7: 1413.12
D8: Assinatura | E8: 1227.5
D9: Delivery/iFood | E9: 1217.92

Sheet 09 CHARTS
A1: CHARTS · Wealth Management Visual Analytics · 2026
